<robot
  name="TBSC_assembly_urdf2">
  <link
    name="fuselage">
    <inertial>
      <origin
        xyz="-0.0349593479683926 0.000331878148872666 0.00735412367732659"
        rpy="0 0 0" />
      <mass
        value="4.1575909457638" />
      <inertia
        ixx="0.185818182108609"
        ixy="-1.52327104962265E-05"
        ixz="-0.000130769919432325"
        iyy="0.0280372247689657"
        iyz="2.88471517246179E-05"
        izz="0.21190998352649" />
    </inertial>
    <visual>
      <origin
        xyz="0 0 0"
        rpy="0 0 0" />
      <geometry>
        <mesh
          filename="../meshes/fuselage.wrl" />
      </geometry>
      <material
        name="">
        <color
          rgba="0.68 0.68 0.68 1" />
      </material>
    </visual>
  </link>
  <link
    name="elevon_left">
    <inertial>
      <origin
        xyz="0.024344339111363 -0.141166243498112 -0.00288253217183636"
        rpy="0 0 0" />
      <mass
        value="0.0503004723155847" />
      <inertia
        ixx="0.000343597911973611"
        ixy="-0.000102664149700067"
        ixz="-6.90528659264952E-07"
        iyy="3.60866683189305E-05"
        iyz="1.09517497875865E-06"
        izz="0.000379357807788057" />
    </inertial>
    <visual>
      <origin
        xyz="0 0 0"
        rpy="0 0 0" />
      <geometry>
        <mesh
          filename="../meshes/elevon_left.wrl" />
      </geometry>
      <material
        name="">
        <color
          rgba="0.984313725490196 1 0.396078431372549 1" />
      </material>
    </visual>
  </link>
  <joint
    name="elevon_left_joint"
    type="continuous">
    <origin
      xyz="-0.210562403107095 0.432529057549488 0.00894564087052806"
      rpy="0 0 0" />
    <parent
      link="fuselage" />
    <child
      link="elevon_left" />
    <axis
      xyz="0.269605075946737 -0.962969468705352 -0.00170451315242792" />
  </joint>
  <link
    name="elevon_right">
    <inertial>
      <origin
        xyz="0.0243440261415946 0.141164212702591 -0.00288253292872706"
        rpy="0 0 0" />
      <mass
        value="0.0503002638510725" />
      <inertia
        ixx="0.000343571434892376"
        ixy="0.00010265713905529"
        ixz="-6.9065341731454E-07"
        iyy="3.60848909803359E-05"
        iyz="-1.09580927322365E-06"
        izz="0.000379329545353445" />
    </inertial>
    <visual>
      <origin
        xyz="0 0 0"
        rpy="0 0 0" />
      <geometry>
        <mesh
          filename="../meshes/elevon_right.wrl" />
      </geometry>
      <material
        name="">
        <color
          rgba="0.984313725490196 1 0.396078431372549 1" />
      </material>
    </visual>
  </link>
  <joint
    name="elevon_right_joint"
    type="continuous">
    <origin
      xyz="-0.210544761310034 -0.432466044967559 0.00894552933457845"
      rpy="0 0 0" />
    <parent
      link="fuselage" />
    <child
      link="elevon_right" />
    <axis
      xyz="0.269605075946737 0.962969468705352 -0.00170451315242805" />
  </joint>
  <link
    name="prop">
    <inertial>
      <origin
        xyz="0.0264162284363671 -2.37906025566202E-08 0.000889743516961591"
        rpy="0 0 0" />
      <mass
        value="0.0158470003258417" />
      <inertia
        ixx="1.93910826369342E-05"
        ixy="-2.23597460424788E-07"
        ixz="-8.44849023246399E-08"
        iyy="4.12864895753647E-06"
        iyz="6.63862731853831E-06"
        izz="1.68855842079905E-05" />
    </inertial>
    <visual>
      <origin
        xyz="0 0 0"
        rpy="0 0 0" />
      <geometry>
        <mesh
          filename="../meshes/prop.wrl" />
      </geometry>
      <material
        name="">
        <color
          rgba="0.250980392156863 0.250980392156863 0.250980392156863 1" />
      </material>
    </visual>
  </link>
  <joint
    name="prop_joint"
    type="continuous">
    <origin
      xyz="-0.149722346596616 0 0.00118718550304035"
      rpy="0 0 0" />
    <parent
      link="fuselage" />
    <child
      link="prop" />
    <axis
      xyz="0.999433245959699 0 0.0336628410931187" />
  </joint>
</robot>
